RUN.SH STARTING !#!#
AUTOGEN_TESTBED_SETTING: [Docker]
Collecting pyautogen (from -r requirements.txt (line 1))
  Downloading pyautogen-0.2.28-py3-none-any.whl.metadata (25 kB)
ERROR: Exception:
Traceback (most recent call last):
  File "/usr/local/lib/python3.11/site-packages/pip/_vendor/urllib3/response.py", line 438, in _error_catcher
    yield
  File "/usr/local/lib/python3.11/site-packages/pip/_vendor/urllib3/response.py", line 561, in read
    data = self._fp_read(amt) if not fp_closed else b""
           ^^^^^^^^^^^^^^^^^^
  File "/usr/local/lib/python3.11/site-packages/pip/_vendor/urllib3/response.py", line 527, in _fp_read
    return self._fp.read(amt) if amt is not None else self._fp.read()
           ^^^^^^^^^^^^^^^^^^
  File "/usr/local/lib/python3.11/site-packages/pip/_vendor/cachecontrol/filewrapper.py", line 98, in read
    data: bytes = self.__fp.read(amt)
                  ^^^^^^^^^^^^^^^^^^^
  File "/usr/local/lib/python3.11/http/client.py", line 473, in read
    s = self.fp.read(amt)
        ^^^^^^^^^^^^^^^^^
  File "/usr/local/lib/python3.11/socket.py", line 706, in readinto
    return self._sock.recv_into(b)
           ^^^^^^^^^^^^^^^^^^^^^^^
  File "/usr/local/lib/python3.11/ssl.py", line 1314, in recv_into
    return self.read(nbytes, buffer)
           ^^^^^^^^^^^^^^^^^^^^^^^^^
  File "/usr/local/lib/python3.11/ssl.py", line 1166, in read
    return self._sslobj.read(len, buffer)
           ^^^^^^^^^^^^^^^^^^^^^^^^^^^^^^
TimeoutError: The read operation timed out

During handling of the above exception, another exception occurred:

Traceback (most recent call last):
  File "/usr/local/lib/python3.11/site-packages/pip/_internal/cli/base_command.py", line 180, in exc_logging_wrapper
    status = run_func(*args)
             ^^^^^^^^^^^^^^^
  File "/usr/local/lib/python3.11/site-packages/pip/_internal/cli/req_command.py", line 245, in wrapper
    return func(self, options, args)
           ^^^^^^^^^^^^^^^^^^^^^^^^^
  File "/usr/local/lib/python3.11/site-packages/pip/_internal/commands/install.py", line 377, in run
    requirement_set = resolver.resolve(
                      ^^^^^^^^^^^^^^^^^
  File "/usr/local/lib/python3.11/site-packages/pip/_internal/resolution/resolvelib/resolver.py", line 95, in resolve
    result = self._result = resolver.resolve(
                            ^^^^^^^^^^^^^^^^^
  File "/usr/local/lib/python3.11/site-packages/pip/_vendor/resolvelib/resolvers.py", line 546, in resolve
    state = resolution.resolve(requirements, max_rounds=max_rounds)
            ^^^^^^^^^^^^^^^^^^^^^^^^^^^^^^^^^^^^^^^^^^^^^^^^^^^^^^^
  File "/usr/local/lib/python3.11/site-packages/pip/_vendor/resolvelib/resolvers.py", line 397, in resolve
    self._add_to_criteria(self.state.criteria, r, parent=None)
  File "/usr/local/lib/python3.11/site-packages/pip/_vendor/resolvelib/resolvers.py", line 173, in _add_to_criteria
    if not criterion.candidates:
  File "/usr/local/lib/python3.11/site-packages/pip/_vendor/resolvelib/structs.py", line 156, in __bool__
    return bool(self._sequence)
           ^^^^^^^^^^^^^^^^^^^^
  File "/usr/local/lib/python3.11/site-packages/pip/_internal/resolution/resolvelib/found_candidates.py", line 155, in __bool__
    return any(self)
           ^^^^^^^^^
  File "/usr/local/lib/python3.11/site-packages/pip/_internal/resolution/resolvelib/found_candidates.py", line 143, in <genexpr>
    return (c for c in iterator if id(c) not in self._incompatible_ids)
           ^^^^^^^^^^^^^^^^^^^^^^^^^^^^^^^^^^^^^^^^^^^^^^^^^^^^^^^^^^^^
  File "/usr/local/lib/python3.11/site-packages/pip/_internal/resolution/resolvelib/found_candidates.py", line 47, in _iter_built
    candidate = func()
                ^^^^^^
  File "/usr/local/lib/python3.11/site-packages/pip/_internal/resolution/resolvelib/factory.py", line 182, in _make_candidate_from_link
    base: Optional[BaseCandidate] = self._make_base_candidate_from_link(
                                    ^^^^^^^^^^^^^^^^^^^^^^^^^^^^^^^^^^^^
  File "/usr/local/lib/python3.11/site-packages/pip/_internal/resolution/resolvelib/factory.py", line 228, in _make_base_candidate_from_link
    self._link_candidate_cache[link] = LinkCandidate(
                                       ^^^^^^^^^^^^^^
  File "/usr/local/lib/python3.11/site-packages/pip/_internal/resolution/resolvelib/candidates.py", line 290, in __init__
    super().__init__(
  File "/usr/local/lib/python3.11/site-packages/pip/_internal/resolution/resolvelib/candidates.py", line 156, in __init__
    self.dist = self._prepare()
                ^^^^^^^^^^^^^^^
  File "/usr/local/lib/python3.11/site-packages/pip/_internal/resolution/resolvelib/candidates.py", line 222, in _prepare
    dist = self._prepare_distribution()
           ^^^^^^^^^^^^^^^^^^^^^^^^^^^^
  File "/usr/local/lib/python3.11/site-packages/pip/_internal/resolution/resolvelib/candidates.py", line 301, in _prepare_distribution
    return preparer.prepare_linked_requirement(self._ireq, parallel_builds=True)
           ^^^^^^^^^^^^^^^^^^^^^^^^^^^^^^^^^^^^^^^^^^^^^^^^^^^^^^^^^^^^^^^^^^^^^
  File "/usr/local/lib/python3.11/site-packages/pip/_internal/operations/prepare.py", line 519, in prepare_linked_requirement
    metadata_dist = self._fetch_metadata_only(req)
                    ^^^^^^^^^^^^^^^^^^^^^^^^^^^^^^
  File "/usr/local/lib/python3.11/site-packages/pip/_internal/operations/prepare.py", line 371, in _fetch_metadata_only
    return self._fetch_metadata_using_link_data_attr(
           ^^^^^^^^^^^^^^^^^^^^^^^^^^^^^^^^^^^^^^^^^^
  File "/usr/local/lib/python3.11/site-packages/pip/_internal/operations/prepare.py", line 391, in _fetch_metadata_using_link_data_attr
    metadata_file = get_http_url(
                    ^^^^^^^^^^^^^
  File "/usr/local/lib/python3.11/site-packages/pip/_internal/operations/prepare.py", line 109, in get_http_url
    from_path, content_type = download(link, temp_dir.path)
                              ^^^^^^^^^^^^^^^^^^^^^^^^^^^^^
  File "/usr/local/lib/python3.11/site-packages/pip/_internal/network/download.py", line 147, in __call__
    for chunk in chunks:
  File "/usr/local/lib/python3.11/site-packages/pip/_internal/network/utils.py", line 63, in response_chunks
    for chunk in response.raw.stream(
  File "/usr/local/lib/python3.11/site-packages/pip/_vendor/urllib3/response.py", line 622, in stream
    data = self.read(amt=amt, decode_content=decode_content)
           ^^^^^^^^^^^^^^^^^^^^^^^^^^^^^^^^^^^^^^^^^^^^^^^^^
  File "/usr/local/lib/python3.11/site-packages/pip/_vendor/urllib3/response.py", line 560, in read
    with self._error_catcher():
  File "/usr/local/lib/python3.11/contextlib.py", line 158, in __exit__
    self.gen.throw(typ, value, traceback)
  File "/usr/local/lib/python3.11/site-packages/pip/_vendor/urllib3/response.py", line 443, in _error_catcher
    raise ReadTimeoutError(self._pool, None, "Read timed out.")
pip._vendor.urllib3.exceptions.ReadTimeoutError: HTTPSConnectionPool(host='files.pythonhosted.org', port=443): Read timed out.
SCENARIO.PY STARTING !#!#
Traceback (most recent call last):
  File "/workspace/scenario.py", line 4, in <module>
    from autogen.agentchat.contrib.capabilities import transform_messages, transforms
ModuleNotFoundError: No module named 'autogen'
SCENARIO.PY EXITED WITH CODE: 1 !#!#
RUN.SH COMPLETE !#!#
